<?xml version="1.0" ?>
<robot name="SGUDeltaRobot" xmlns:xacro="http://ros.org/wiki/xacro">
 <xacro:include filename="$(find delta_robot)/urdf/delta_arm_robot_macro.xacro"/>

  <xacro:macro name="delta" params="prefix">

    <!-- Base Link -->

    <link name="${prefix}base_link">
    <inertial>
      <origin
        xyz="-7.9508E-05 0.0014541 -0.020718"
        rpy="0 0 0" />
      <mass
        value="0.25874" />
      <inertia
        ixx="0.00088292"
        ixy="-5.3647E-10"
        ixz="-2.4389E-07"
        iyy="0.00088293"
        iyz="-1.4077E-07"
        izz="0.0015757" />
    </inertial>
      <visual>
        <origin xyz="0 0 0" rpy="0 0 0" />
        <geometry>
          <mesh filename="package://delta_robot/meshes/base_link.STL" />
        </geometry>
        <material name="">
          <color rgba="0.75294 0.75294 0.75294 1" />
        </material>
      </visual>
      <collision>
        <origin xyz="0 0 0" rpy="0 0 0" />
        <geometry>
          <mesh filename="package://delta_robot/meshes/base_link.STL" />
        </geometry>
      </collision>
    </link>

    <!-- The Arms -->

    <xacro:delta_arm prefix="${prefix}" num="1" x="-0.078024" y="-0.045047" z="-0.044771" r="-1.3676" p="1.249E-16" w="-1.0472" dxa="-0.19542" dya="-0.13554" dza="-0.075045" dra="0.22358" dpa="0.93658" dwa="0.46912" dxb="-0.21742" dyb="-0.097439" dzb="-0.075045" drb="2.9003" dpb="0.93675" dwb="0.47415"/>

    <xacro:delta_arm prefix="${prefix}" num="2" x="0.077837" y="-0.044939" z="-0.044771" r="-1.4054" p="-5.5511E-17" w="1.0472" dxa="0.19504" dya="-0.13784" dza="-0.06946" dra="2.9065" dpa="0.96648" dwa="2.6369" dxb="0.21704" dyb="-0.099734" dzb="-0.06946" drb="0.24077" dpb="0.96656" dwb="2.6317"/>

    <xacro:delta_arm prefix="${prefix}" num="3" x="0" y="0.092128" z="-0.044771" r="-1.3341" p="-6.5885E-17" w="3.1416" dxa="-0.0211" dya="-0.13784" dza="-0.079949" dra="0.010531" dpa="0.91496" dwa="-1.553" dxb="0.0229" dyb="0.23794" dzb="-0.079949" drb="-2.9003" dpb="0.91486" dwb="-1.5481"/>

    <!-- End Effector Link -->

    <link name="${prefix}ee_link">
    <inertial>
      <origin
        xyz="1.2588E-11 2.0688E-10 -0.005"
        rpy="0 0 0" />
      <mass
        value="0.037637" />
      <inertia
        ixx="2.2295E-05"
        ixy="6.2216E-15"
        ixz="-2.154E-08"
        iyy="2.2295E-05"
        iyz="-3.7307E-08"
        izz="4.4E-05" />
    </inertial>
      <visual>
        <origin xyz="0 0 0" rpy="0 0 0" />
        <geometry>
          <mesh filename="package://delta_robot/meshes/ee_link.STL" />
        </geometry>
        <material name="">
          <color rgba="0.75294 0.75294 0.75294 1" />
        </material>
      </visual>
      <collision>
        <origin xyz="0 0 0" rpy="0 0 0" />
        <geometry>
          <mesh filename="package://delta_robot/meshes/ee_link.STL" />
        </geometry>
      </collision>
    </link>
    <joint name="${prefix}ee_joint" type="floating">
      <origin xyz="0.0050361 -0.0063137 -0.34016" rpy="0.00063172 0.00043496 3.1415" />
      <parent link="${prefix}base_link" />
      <child link="${prefix}ee_link" />
    </joint>

    <!-- Tool0 for compliance with ROS-I protocols -->

    <link name="${prefix}tool0"/>
    <joint name="${prefix}ee_link_to_tool0" type="fixed">
      <parent link="${prefix}ee_link"/>
      <child link="${prefix}tool0"/>
    </joint>

  </xacro:macro>
</robot>
