<?xml version="1.0" ?>
<!-- =================================================================================== -->
<!-- |    This document was autogenerated by xacro from delta_robot.xacro              | -->
<!-- |    EDITING THIS FILE BY HAND IS NOT RECOMMENDED                                 | -->
<!-- =================================================================================== -->
<robot name="SGUDeltaRobot" xmlns:xacro="http://ros.org/wiki/xacro">
  <link name="world"/>
  <!-- Base Link -->
  <link name="base_link">
    <inertial>
      <origin rpy="0 0 0" xyz="-7.9508E-05 0.0014541 -0.020718"/>
      <mass value="0.25874"/>
      <inertia ixx="0.00088292" ixy="-5.3647E-10" ixz="-2.4389E-07" iyy="0.00088293" iyz="-1.4077E-07" izz="0.0015757"/>
    </inertial>
    <visual>
      <origin rpy="0 0 0" xyz="0 0 0"/>
      <geometry>
        <mesh filename="package://delta_robot/meshes/base_link.STL"/>
      </geometry>
      <material name="">
        <color rgba="0.75294 0.75294 0.75294 1"/>
      </material>
    </visual>
    <collision>
      <origin rpy="0 0 0" xyz="0 0 0"/>
      <geometry>
        <mesh filename="package://delta_robot/meshes/base_link.STL"/>
      </geometry>
    </collision>
  </link>
  <!-- The Arms -->
  <!-- Upper Arm -->
  <link name="upper_arm_1">
    <visual>
      <origin rpy="0 0 0" xyz="0 0 0"/>
      <geometry>
        <mesh filename="package://delta_robot/meshes/upper_arm_1.STL"/>
      </geometry>
      <material name="">
        <color rgba="0.75294 0.75294 0.75294 1"/>
      </material>
    </visual>
    <collision>
      <origin rpy="0 0 0" xyz="0 0 0"/>
      <geometry>
        <mesh filename="package://delta_robot/meshes/upper_arm_1.STL"/>
      </geometry>
    </collision>
  </link>
  <joint name="joint_1" type="revolute">
    <origin rpy="-1.3676 1.249e-16 -1.0472" xyz="-0.078024 -0.045047 -0.044771"/>
    <parent link="base_link"/>
    <child link="upper_arm_1"/>
    <axis xyz="1.0 0 0"/>
    <limit effort="10" lower="-0.71" upper="1.5" velocity="2.618"/>
  </joint>
  <!-- Lower Arm a -->
  <link name="lower_arm_1a">
    <visual>
      <origin rpy="0 0 0" xyz="0 0 0"/>
      <geometry>
        <mesh filename="package://delta_robot/meshes/lower_arm.STL"/>
      </geometry>
      <material name="">
        <color rgba="0.75294 0.75294 0.75294 1"/>
      </material>
    </visual>
    <collision>
      <origin rpy="0 0 0" xyz="0 0 0"/>
      <geometry>
        <mesh filename="package://delta_robot/meshes/lower_arm.STL"/>
      </geometry>
    </collision>
  </link>
  <joint name="a1_j2a" type="floating">
    <origin rpy="0.22358 0.93658 0.46912" xyz="-0.19542 -0.13554 -0.075045"/>
    <parent link="upper_arm_1"/>
    <child link="lower_arm_1a"/>
  </joint>
  <!-- Lower Arm b -->
  <link name="lower_arm_1b">
    <visual>
      <origin rpy="0 0 0" xyz="0 0 0"/>
      <geometry>
        <mesh filename="package://delta_robot/meshes/lower_arm.STL"/>
      </geometry>
      <material name="">
        <color rgba="0.75294 0.75294 0.75294 1"/>
      </material>
    </visual>
    <collision>
      <origin rpy="0 0 0" xyz="0 0 0"/>
      <geometry>
        <mesh filename="package://delta_robot/meshes/lower_arm.STL"/>
      </geometry>
    </collision>
  </link>
  <joint name="a1_j2b" type="floating">
    <origin rpy="2.9003 0.93675 0.47415" xyz="-0.21742 -0.097439 -0.075045"/>
    <parent link="upper_arm_1"/>
    <child link="lower_arm_1b"/>
  </joint>
  <!-- Upper Arm -->
  <link name="upper_arm_2">
    <visual>
      <origin rpy="0 0 0" xyz="0 0 0"/>
      <geometry>
        <mesh filename="package://delta_robot/meshes/upper_arm_2.STL"/>
      </geometry>
      <material name="">
        <color rgba="0.75294 0.75294 0.75294 1"/>
      </material>
    </visual>
    <collision>
      <origin rpy="0 0 0" xyz="0 0 0"/>
      <geometry>
        <mesh filename="package://delta_robot/meshes/upper_arm_2.STL"/>
      </geometry>
    </collision>
  </link>
  <joint name="joint_2" type="revolute">
    <origin rpy="-1.4054 -5.5511e-17 1.0472" xyz="0.077837 -0.044939 -0.044771"/>
    <parent link="base_link"/>
    <child link="upper_arm_2"/>
    <axis xyz="1.0 0 0"/>
    <limit effort="10" lower="-0.71" upper="1.5" velocity="2.618"/>
  </joint>
  <!-- Lower Arm a -->
  <link name="lower_arm_2a">
    <visual>
      <origin rpy="0 0 0" xyz="0 0 0"/>
      <geometry>
        <mesh filename="package://delta_robot/meshes/lower_arm.STL"/>
      </geometry>
      <material name="">
        <color rgba="0.75294 0.75294 0.75294 1"/>
      </material>
    </visual>
    <collision>
      <origin rpy="0 0 0" xyz="0 0 0"/>
      <geometry>
        <mesh filename="package://delta_robot/meshes/lower_arm.STL"/>
      </geometry>
    </collision>
  </link>
  <joint name="a2_j2a" type="floating">
    <origin rpy="2.9065 0.96648 2.6369" xyz="0.19504 -0.13784 -0.06946"/>
    <parent link="upper_arm_2"/>
    <child link="lower_arm_2a"/>
  </joint>
  <!-- Lower Arm b -->
  <link name="lower_arm_2b">
    <visual>
      <origin rpy="0 0 0" xyz="0 0 0"/>
      <geometry>
        <mesh filename="package://delta_robot/meshes/lower_arm.STL"/>
      </geometry>
      <material name="">
        <color rgba="0.75294 0.75294 0.75294 1"/>
      </material>
    </visual>
    <collision>
      <origin rpy="0 0 0" xyz="0 0 0"/>
      <geometry>
        <mesh filename="package://delta_robot/meshes/lower_arm.STL"/>
      </geometry>
    </collision>
  </link>
  <joint name="a2_j2b" type="floating">
    <origin rpy="0.24077 0.96656 2.6317" xyz="0.21704 -0.099734 -0.06946"/>
    <parent link="upper_arm_2"/>
    <child link="lower_arm_2b"/>
  </joint>
  <!-- Upper Arm -->
  <link name="upper_arm_3">
    <visual>
      <origin rpy="0 0 0" xyz="0 0 0"/>
      <geometry>
        <mesh filename="package://delta_robot/meshes/upper_arm_3.STL"/>
      </geometry>
      <material name="">
        <color rgba="0.75294 0.75294 0.75294 1"/>
      </material>
    </visual>
    <collision>
      <origin rpy="0 0 0" xyz="0 0 0"/>
      <geometry>
        <mesh filename="package://delta_robot/meshes/upper_arm_3.STL"/>
      </geometry>
    </collision>
  </link>
  <joint name="joint_3" type="revolute">
    <origin rpy="-1.3341 -6.5885e-17 3.1416" xyz="0 0.092128 -0.044771"/>
    <parent link="base_link"/>
    <child link="upper_arm_3"/>
    <axis xyz="1.0 0 0"/>
    <limit effort="10" lower="-0.71" upper="1.5" velocity="2.618"/>
  </joint>
  <!-- Lower Arm a -->
  <link name="lower_arm_3a">
    <visual>
      <origin rpy="0 0 0" xyz="0 0 0"/>
      <geometry>
        <mesh filename="package://delta_robot/meshes/lower_arm.STL"/>
      </geometry>
      <material name="">
        <color rgba="0.75294 0.75294 0.75294 1"/>
      </material>
    </visual>
    <collision>
      <origin rpy="0 0 0" xyz="0 0 0"/>
      <geometry>
        <mesh filename="package://delta_robot/meshes/lower_arm.STL"/>
      </geometry>
    </collision>
  </link>
  <joint name="a3_j2a" type="floating">
    <origin rpy="0.010531 0.91496 -1.553" xyz="-0.0211 -0.13784 -0.079949"/>
    <parent link="upper_arm_3"/>
    <child link="lower_arm_3a"/>
  </joint>
  <!-- Lower Arm b -->
  <link name="lower_arm_3b">
    <visual>
      <origin rpy="0 0 0" xyz="0 0 0"/>
      <geometry>
        <mesh filename="package://delta_robot/meshes/lower_arm.STL"/>
      </geometry>
      <material name="">
        <color rgba="0.75294 0.75294 0.75294 1"/>
      </material>
    </visual>
    <collision>
      <origin rpy="0 0 0" xyz="0 0 0"/>
      <geometry>
        <mesh filename="package://delta_robot/meshes/lower_arm.STL"/>
      </geometry>
    </collision>
  </link>
  <joint name="a3_j2b" type="floating">
    <origin rpy="-2.9003 0.91486 -1.5481" xyz="0.0229 0.23794 -0.079949"/>
    <parent link="upper_arm_3"/>
    <child link="lower_arm_3b"/>
  </joint>
  <!-- End Effector Link -->
  <link name="ee_link">
    <inertial>
      <origin rpy="0 0 0" xyz="1.2588E-11 2.0688E-10 -0.005"/>
      <mass value="0.037637"/>
      <inertia ixx="2.2295E-05" ixy="6.2216E-15" ixz="-2.154E-08" iyy="2.2295E-05" iyz="-3.7307E-08" izz="4.4E-05"/>
    </inertial>
    <visual>
      <origin rpy="0 0 0" xyz="0 0 0"/>
      <geometry>
        <mesh filename="package://delta_robot/meshes/ee_link.STL"/>
      </geometry>
      <material name="">
        <color rgba="0.75294 0.75294 0.75294 1"/>
      </material>
    </visual>
    <collision>
      <origin rpy="0 0 0" xyz="0 0 0"/>
      <geometry>
        <mesh filename="package://delta_robot/meshes/ee_link.STL"/>
      </geometry>
    </collision>
  </link>
  <joint name="ee_joint" type="floating">
    <origin rpy="0.00063172 0.00043496 3.1415" xyz="0.0050361 -0.0063137 -0.34016"/>
    <parent link="base_link"/>
    <child link="ee_link"/>
  </joint>
  <!-- Tool0 for compliance with ROS-I protocols -->
  <link name="tool0"/>
  <joint name="ee_link_to_tool0" type="fixed">
    <parent link="ee_link"/>
    <child link="tool0"/>
  </joint>
  <joint name="world_to_delta" type="fixed">
    <parent link="world"/>
    <child link="base_link"/>
    <origin xyz="0 0 0"/>
  </joint>
</robot>
